
============================================================
Computing k=0 baseline (identity prediction)
============================================================
Baseline MSE: 23.7727
Baseline RÂ²: -299.2810
Training 3 probes in parallel...
concurrent.futures.process._RemoteTraceback: 
"""
Traceback (most recent call last):
  File "/usr/lib/python3.11/multiprocessing/queues.py", line 244, in _feed
    obj = _ForkingPickler.dumps(obj)
          ^^^^^^^^^^^^^^^^^^^^^^^^^^
  File "/usr/lib/python3.11/multiprocessing/reduction.py", line 51, in dumps
    cls(buf, protocol).dump(obj)
AttributeError: Can't pickle local object 'main.<locals>.train_single_k'
"""

The above exception was the direct cause of the following exception:

Traceback (most recent call last):
  File "/root/itxc/temporal_xc/train_probe.py", line 739, in <module>
    main()
  File "/root/itxc/temporal_xc/train_probe.py", line 608, in main
    k_value, probe_results, trainer = future.result()
                                      ^^^^^^^^^^^^^^^
  File "/usr/lib/python3.11/concurrent/futures/_base.py", line 449, in result
    return self.__get_result()
           ^^^^^^^^^^^^^^^^^^^
  File "/usr/lib/python3.11/concurrent/futures/_base.py", line 401, in __get_result
    raise self._exception
  File "/usr/lib/python3.11/multiprocessing/queues.py", line 244, in _feed
    obj = _ForkingPickler.dumps(obj)
          ^^^^^^^^^^^^^^^^^^^^^^^^^^
  File "/usr/lib/python3.11/multiprocessing/reduction.py", line 51, in dumps
    cls(buf, protocol).dump(obj)
AttributeError: Can't pickle local object 'main.<locals>.train_single_k'
